Workbook

Sheet Synthèses et indicateurs EHS
A3: Agence de | P3: Date de mise à jour :
B7: ='Suivi des AT'!I3 -> 6977
B14: jours sans Accidents du Travail
E20: Inpections | M20: Audits | X20: Communications
E21: EPI | I21: Véhicules | M21: Audits de Services | Q21: Visites terrains | X21: Causeries
E22: % avancement | I22: Insp. Réalisées | M22: % avancement | Q22: Insp. Réalisées | X22: % avancement | AA22: Causerie Q1
E23: ='Gestion EHS'!O7 -> #DIV/0! | I23: ='Gestion EHS'!Y7 -> #DIV/0! | M23: ='Gestion EHS'!AL7 -> #DIV/0! | Q23: ='Gestion EHS'!AF7 -> #DIV/0! | X23: =IF(AA22="Causerie Q1",'Gestion EHS'!BA7,IF(AA22="Causerie Q2",'Gestion EHS'!BC7,IF(AA22="Causerie Q3",'Gestion EHS'!BE7,IF(AA22="Causerie Q4",'Gestion EHS'!BG7)))) -> #DIV/0!
F28: Suivi des actions (Issues des visites terrains, des audits, des comités EHS…) | R28: Nombre de Situations Dangereuses remontées
F30: % avancement | J30: Nb d'actions | N30: Actions dépassées | R30: ='Suivi des actions Qualite-EHS'!G4 -> 0
F31: ='Suivi des actions Qualite-EHS'!N4 -> #DIV/0! | J31: ='Suivi des actions Qualite-EHS'!B4 -> 0 | N31: ='Suivi des actions Qualite-EHS'!C4 -> 0

Sheet Objectifs annuels
A1: Objectifs annuels 2019
A2: Agence : | C2: Directeur d'Agence : | D2: Avancement global : | E2: =AVERAGE(B11,B20,B29,B38) -> #DIV/0! | G2: Date de mise à jour :
C3: Objectifs et Actions | D3: Responsable | E3: Délai | G3: Acteurs | H3: Moyens | I3: Indicateurs | K3: Exigences | L3: Efficacité attendue | M3: Commentaires
E4: Période | F4: % d'avancement | I4: De résultat | J4: De surveillance
A5: Objectifs Management
B9: Avancement Management
B11: =AVERAGE(F6,F7,F9,F10,F12,F13) -> #DIV/0!
A14: Objectifs Environnement
B18: Avancement Environnement
B20: =AVERAGE(F15:F16,F18:F19,F21:F22) -> #DIV/0!
A23: Objectifs Hygiène/Santé
B27: Avancement Hygiène/Santé
B29: =AVERAGE(F24:F25,F27:F28,F30:F31) -> #DIV/0!
A32: Objectifs Sécurité
B36: Avancement Sécurité
B38: =AVERAGE(F33:F34,F36:F37,F39:F40) -> #DIV/0!

Sheet Gestion EHS
A1: Suivi des Inspections et des communications EHS
AF2: =AF7 -> #DIV/0! | AL2: =AL7 -> #DIV/0!
A3: Agence installant/réalisant des maintenances d''extinction automatique ? | E3: Oui
A4: Agence installant/réalisant des maintenances de désenfumage ? | E4: Oui
L5: Objectif | O5: Réalisé | V5: Objectif | Y5: Réalisé | AC5: Objectif | AF5: Réalisé | AJ5: Objectif | AL5: Réalisé | AO5: Objectif | AR5: Réalisé | AT5: Objectif | AW5: Réalisé | BA5: Taux de réalisation | BC5: Taux de réalisation | BE5: Taux de réalisation | BG5: Taux de réalisation
E6: Effectif | L6: =SUM(M14:M100) -> 0 | O6: =COUNTA(N14:N391) -> 0 | V6: =SUM(W14:W100) -> 0 | Y6: =COUNTA(X14:X391) -> 0 | AC6: =SUM(AD14:AD100) -> 0 | AF6: =COUNTA(AE14:AE391) -> 0 | AJ6: 0 | AL6: =COUNTA(AJ14:AJ100) -> 0 | AO6: 0 | AR6: =COUNTA(AO14:AO391,AP14:AP391) -> 0 | AW6: =COUNTA(AT14:AW100) -> 0
A7: Date : | B7: =TODAY() -> 43503 | E7: =COUNTIFS(H14:H402,"oui") -> 0 | L7: % avancement | O7: =O6/L6 -> #DIV/0! | V7: % avancement | Y7: =Y6/V6 -> #DIV/0! | AC7: % avancement | AF7: =AF6/AC6 -> #DIV/0! | AJ7: % avancement | AL7: =AL6/AJ6 -> #DIV/0! | AO7: % avancement | AQ7: =AR6/AO6 -> #DIV/0! | AT7: % avancement | AW7: =AW6/AT6 -> #DIV/0! | BA7: =COUNTA(BA14:BA217)/$E$7 -> #DIV/0! | BC7: =COUNTA(BC14:BC217)/$E$7 -> #DIV/0! | BE7: =COUNTA(BE14:BE217)/$E$7 -> #DIV/0! | BG7: =COUNTA(BG14:BG217)/$E$7 -> #DIV/0!
A8: Agence | B8: Etablissement | C8: Nom | D8: Prénom | E8: Fonction | F8: Service | G8: Statut | H8: Effectif agence ? | I8: INSPECTIONS | BA8: CAUSERIES EHS | BI8: Comités EHS | BM8: Nombre de remontées d'informations (dont Situations Dangereuses et Bonnes Pratiques)
I9: Inspections EPI | S9: Inspections véhicule | AC9: Visites terrain | AJ9: Audits de service | AO9: Visite désenfumage | AT9: Visite Equipements sous pression | BA9: Causerie Q1 | BC9: Causerie Q2 | BE9: Causerie Q3 | BG9: Causerie Q4 | BI9: Agence
I10: Auto-inspections | L10: Inspection par N+1 | S10: Auto-inspections | V10: Inspection par N+1 | AC10: Planning | AE10: Date réalisation | AF10: Par | AG10: ACTIONS | AJ10: Date réalisation | AK10: Par | AL10: ACTIONS | AO10: S1 | AP10: S2 | AQ10: ACTIONS | AX10: ACTIONS | BA10: Date de parution | BC10: Date de parution | BE10: Date de parution | BG10: Date de parution | BI10: Q1 | BJ10: Q2 | BK10: Q3 | BL10: Q4
I11: Date réalisation | J11: ACTIONS | L11: Planning | N11: Date réalisation | O11: Par | P11: ACTIONS | S11: Date réalisation | T11: ACTIONS | V11: Planning | X11: Date réalisation | Y11: Par | Z11: ACTIONS | AG11: A solder | AH11: Date | AL11: A solder | AM11: Date | AQ11: A solder | AR11: Date | AX11: A solder | AY11: Date
J12: A solder | K12: Date | P12: A solder | Q12: Date | T12: A solder | U12: Date | Z12: A solder | AA12: Date
AT13: =COUNTA(AT14:AT274) -> 0 | AU13: =COUNTA(AU88:AU274) -> 0 | AV13: =COUNTA(AV88:AV274) -> 0 | AW13: =COUNTA(AW88:AW274) -> 0 | BA13: Date | BB13: Par | BC13: Date | BD13: Par | BE13: Date | BF13: Par | BG13: Date | BH13: Par
AD14: =IF(ISBLANK(C14),"",(IF(AC14<>"NA",1,0)))
AD15: =IF(ISBLANK(C15),"",(IF(AC15<>"NA",1,0)))
AD16: =IF(ISBLANK(C16),"",(IF(AC16<>"NA",1,0)))
AD17: =IF(ISBLANK(C17),"",(IF(AC17<>"NA",1,0)))
AD19: =IF(ISBLANK(C19),"",(IF(AC19<>"NA",1,0)))
AD20: =IF(ISBLANK(C20),"",(IF(AC20<>"NA",1,0)))
AD21: =IF(ISBLANK(C21),"",(IF(AC21<>"NA",1,0)))
AD22: =IF(ISBLANK(C22),"",(IF(AC22<>"NA",1,0)))
AD23: =IF(ISBLANK(C23),"",(IF(AC23<>"NA",1,0)))
AD24: =IF(ISBLANK(C24),"",(IF(AC24<>"NA",1,0)))
AD25: =IF(ISBLANK(C25),"",(IF(AC25<>"NA",1,0)))
AD26: =IF(ISBLANK(C26),"",(IF(AC26<>"NA",1,0)))
... AD94: =IF(ISBLANK(C94),"",(IF(AC94<>"NA",1,0)))
W95: =IF(ISBLANK(C95),"",(IF(V95<>"NA",1,0))) | AD95: =IF(ISBLANK(C95),"",(IF(AC95<>"NA",1,0)))
W96: =IF(ISBLANK(C96),"",(IF(V96<>"NA",1,0))) | AD96: =IF(ISBLANK(C96),"",(IF(AC96<>"NA",1,0)))
W97: =IF(ISBLANK(C97),"",(IF(V97<>"NA",1,0))) | AD97: =IF(ISBLANK(C97),"",(IF(AC97<>"NA",1,0)))
W98: =IF(ISBLANK(C98),"",(IF(V98<>"NA",1,0))) | AD98: =IF(ISBLANK(C98),"",(IF(AC98<>"NA",1,0)))
W99: =IF(ISBLANK(C99),"",(IF(V99<>"NA",1,0))) | AD99: =IF(ISBLANK(C99),"",(IF(AC99<>"NA",1,0)))
W100: =IF(ISBLANK(C100),"",(IF(V100<>"NA",1,0))) | AD100: =IF(ISBLANK(C100),"",(IF(AC100<>"NA",1,0)))

Sheet Suivi des actions Qualite-EHS
A1: Plan d'action QUALITE - SECURITE - ENVIRONNEMENT Suivi des Actions Correctives (AC) et des Actions Préventives (AP)
B2: Date de mise à jour : | E2: =TODAY() -> 43503
B3: Nombre total d'actions | C3: Nombre d'actions dépassées | D3: Nombre d'actions sans échéance | E3: Pour les situations dangereuses, indiquer la conséquence potentielle : - Sécurité : 1 (bénin) ; 2 (AT sans arrêt) ; 3 (AT avec arrêt) ; 4 (Irréversible ou mortelle) - Environnement : 1 (mauvais tri déchets) ; 2 (Renversement produit) ; 3 (Percussion accidentelle de réservoirs fluorés) ; 4 (incendie dans local d'activité) Selon les circonstances et la gravité potentielle de la situation dangereuse, une analyse détaillée de l'événement peut être décidée en comité EHS. A minima, une analyse est réalisée à partir du niveau 2 | G3: Nombre total de SD Sécurité ou Environnement / Presqu'AT | J3: Priorité HAUTE = actions liées à AT, réglementation et règles cardinales Les actions doivent être mises en place au maximum de 30 jours Priorité AUTRES = Actions mises en place dans les 9 mois | N3: Avancement des actions
B4: =COUNTA(E7:E300) -> 0 | C4: =SUM(Q7:Q300) -> 0 | D4: =SUM(S7:S300) -> 0 | G4: =COUNTIF(G7:G530,"Oui") -> 0 | N4: =SUBTOTAL(1,N7:N470) -> #DIV/0!
B5: Date | C5: Etablissement | D5: Source | E5: Qualité et EHS : Dysfonctionnement / Anomalie Amélioration | F5: Cause | G5: Situation dangereuse Presqu'accident | J5: Action | K5: Responsable d'action | L5: Priorité | M5: Délai | N5: % Avancement | O5: Statut/Commentaire de l'avancement | P5: Date de réalisation | Q5: éch. Dépassées | R5: Nb actions | S5: Sans délai | T5: Catégorisation de l'action | Y5: Vérification et Efficacité de l'action
G6: ? | H6: SD remontée par | I6: Evaluation conséquence | T6: Thème | U6: Domaine Type de risque | V6: QUALITE Analyse 6M | W6: Type d'action | X6: Principe de prévention associé | Y6: Date de vérification | Z6: Non récurrence | AA6: Respect de la réglementation | AB6: Non transfert du risque | AC6: Commentaires
Q7: =IF(N7=100%,0,IF(M7>=TODAY(),0,IF(ISBLANK(M7),0,1))) -> 0 | R7: =IF(COUNTBLANK(E7),0,1) -> 0 | S7: =IF(AND(R7=1,COUNTBLANK(M7),N7<100%),1,0) -> 0
Q8: =IF(N8=100%,0,IF(M8>=TODAY(),0,IF(ISBLANK(M8),0,1))) -> 0 | R8: =IF(COUNTBLANK(E8),0,1) -> 0 | S8: =IF(AND(R8=1,COUNTBLANK(M8),N8<100%),1,0) -> 0
Q9: =IF(N9=100%,0,IF(M9>=TODAY(),0,IF(ISBLANK(M9),0,1))) -> 0 | R9: =IF(COUNTBLANK(E9),0,1) -> 0 | S9: =IF(AND(R9=1,COUNTBLANK(M9),N9<100%),1,0) -> 0
Q10: =IF(N10=100%,0,IF(M10>=TODAY(),0,IF(ISBLANK(M10),0,1))) -> 0 | R10: =IF(COUNTBLANK(E10),0,1) -> 0 | S10: =IF(AND(R10=1,COUNTBLANK(M10),N10<100%),1,0) -> 0
Q11: =IF(N11=100%,0,IF(M11>=TODAY(),0,IF(ISBLANK(M11),0,1))) -> 0 | R11: =IF(COUNTBLANK(E11),0,1) -> 0 | S11: =IF(AND(R11=1,COUNTBLANK(M11),N11<100%),1,0) -> 0
Q12: =IF(N12=100%,0,IF(M12>=TODAY(),0,IF(ISBLANK(M12),0,1))) -> 0 | R12: =IF(COUNTBLANK(E12),0,1) -> 0 | S12: =IF(AND(R12=1,COUNTBLANK(M12),N12<100%),1,0) -> 0
Q13: =IF(N13=100%,0,IF(M13>=TODAY(),0,IF(ISBLANK(M13),0,1))) -> 0 | R13: =IF(COUNTBLANK(E13),0,1) -> 0 | S13: =IF(AND(R13=1,COUNTBLANK(M13),N13<100%),1,0) -> 0
Q14: =IF(N14=100%,0,IF(M14>=TODAY(),0,IF(ISBLANK(M14),0,1))) -> 0 | R14: =IF(COUNTBLANK(E14),0,1) -> 0 | S14: =IF(AND(R14=1,COUNTBLANK(M14),N14<100%),1,0) -> 0
Q15: =IF(N15=100%,0,IF(M15>=TODAY(),0,IF(ISBLANK(M15),0,1))) -> 0 | R15: =IF(COUNTBLANK(E15),0,1) -> 0 | S15: =IF(AND(R15=1,COUNTBLANK(M15),N15<100%),1,0) -> 0
Q16: =IF(N16=100%,0,IF(M16>=TODAY(),0,IF(ISBLANK(M16),0,1))) -> 0 | R16: =IF(COUNTBLANK(E16),0,1) -> 0 | S16: =IF(AND(R16=1,COUNTBLANK(M16),N16<100%),1,0) -> 0
Q17: =IF(N17=100%,0,IF(M17>=TODAY(),0,IF(ISBLANK(M17),0,1))) -> 0 | R17: =IF(COUNTBLANK(E17),0,1) -> 0 | S17: =IF(AND(R17=1,COUNTBLANK(M17),N17<100%),1,0) -> 0
Q18: =IF(N18=100%,0,IF(M18>=TODAY(),0,IF(ISBLANK(M18),0,1))) -> 0 | R18: =IF(COUNTBLANK(E18),0,1) -> 0 | S18: =IF(AND(R18=1,COUNTBLANK(M18),N18<100%),1,0) -> 0
... Q300: =IF(N300=100%,0,IF(M300>=TODAY(),0,IF(ISBLANK(M300),0,1))) -> 0 | R300: =IF(COUNTBLANK(E300),0,1) -> 0 | S300: =IF(AND(R300=1,COUNTBLANK(M300),N300<100%),1,0) -> 0

Sheet Suivi des AT
A1: Suivi des Accidents du Travail
F3: Date du dernier AT : | G3: 36526 | H3: Nb de jours sans AT | I3: =A4-G3 -> 6977
A4: =TODAY() -> 43503
A6: Agence | B6: Localisation | C6: Date de l'accident | D6: Victime | E6: Type d'AT | F6: Date de retour | G6: Nombre de jours d'arrêt | H6: Date analyse des causes | I6: Visite médicale de reprise | J6: visite de reprise faite
G8: =IF(E8<>"ATAA","",F8-C8-1) | I8: =IF(E8<>"ATAA","",(IF(G8>29,"visite de reprise obligatoire","Pas nécessaire")))
G9: =IF(E9<>"ATAA","",F9-C9-1) | I9: =IF(E9<>"ATAA","",(IF(G9>29,"visite de reprise obligatoire","Pas nécessaire")))
G10: =IF(E10<>"ATAA","",F10-C10-1) | I10: =IF(E10<>"ATAA","",(IF(G10>29,"visite de reprise obligatoire","Pas nécessaire")))
G11: =IF(E11<>"ATAA","",F11-C11-1) | I11: =IF(E11<>"ATAA","",(IF(G11>29,"visite de reprise obligatoire","Pas nécessaire")))
G12: =IF(E12<>"ATAA","",F12-C12-1) | I12: =IF(E12<>"ATAA","",(IF(G12>29,"visite de reprise obligatoire","Pas nécessaire")))
G13: =IF(E13<>"ATAA","",F13-C13-1) | I13: =IF(E13<>"ATAA","",(IF(G13>29,"visite de reprise obligatoire","Pas nécessaire")))
G14: =IF(E14<>"ATAA","",F14-C14-1) | I14: =IF(E14<>"ATAA","",(IF(G14>29,"visite de reprise obligatoire","Pas nécessaire")))
G15: =IF(E15<>"ATAA","",F15-C15-1) | I15: =IF(E15<>"ATAA","",(IF(G15>29,"visite de reprise obligatoire","Pas nécessaire")))
G16: =IF(E16<>"ATAA","",F16-C16-1) | I16: =IF(E16<>"ATAA","",(IF(G16>29,"visite de reprise obligatoire","Pas nécessaire")))
G17: =IF(E17<>"ATAA","",F17-C17-1) | I17: =IF(E17<>"ATAA","",(IF(G17>29,"visite de reprise obligatoire","Pas nécessaire")))
G18: =IF(E18<>"ATAA","",F18-C18-1) | I18: =IF(E18<>"ATAA","",(IF(G18>29,"visite de reprise obligatoire","Pas nécessaire")))
G19: =IF(E19<>"ATAA","",F19-C19-1) | I19: =IF(E19<>"ATAA","",(IF(G19>29,"visite de reprise obligatoire","Pas nécessaire")))

Sheet Suivi des Sinistres Auto
A1: Suivi des Sinistres Automobiles
A3: Tableau à remplir dès la rédaction d'un constat amiable
A5: Date | B5: Heure | C5: Genre collision | D5: Type collision | E5: Commentaires | F5: Responsabilité ?
A33: =COUNTA(A7:A32) -> 0 | E33: Oui | F33: =COUNTIF(F7:F32,E33) -> 0
E34: Non | F34: =COUNTIF(F8:F33,E34) -> 0

Sheet Contrôles réglementaires
A1: Contrôles réglementaires Agence, magasin et dépôts
A2: Date : | B2: =TODAY() -> 43503
A3: Type de vérification | B3: Objet de la vérification | C3: Elément cible | D3: Localisation | E3: Applicable au site | F3: Périodicité (année) | G3: Date de dernière réalisation | H3: Nombre d'observations | I3: Nombre d'observations levées | J3: Nombre d'observations à lever | K3: Date planif prochain contrôle | L3: Date échéance prochaine réalisation | M3: Rapport n° | N3: Commentaires
A4: Installations Electriques | B4: Contrôle de l'installation complète | C4: Agence | E4: NON | F4: 1 | J4: =IF(E4="Non","",IF(H4=0,"NA",H4-I4)) | L4: =IF(G4="","",IF(G4="NA","_",G4+(F4*365)))
A5: Installations Electriques | B5: Thermographie Infra-rouge + Q18 | C5: Agence | E5: NON | F5: 1 | J5: =IF(E5="Non","",IF(H5=0,"NA",H5-I5)) | L5: =IF(G5="","",IF(G5="NA","_",G5+(F5*365)))
A6: Incendie | B6: Extincteurs | C6: Agence | E6: NON | F6: 1 | J6: =IF(E6="Non","",IF(H6=0,"NA",H6-I6)) | L6: =IF(G6="","",IF(G6="NA","_",G6+(F6*365)))
A7: Incendie | B7: BAES | C7: Agence | E7: NON | F7: 1 | J7: =IF(E7="Non","",IF(H7=0,"NA",H7-I7)) | L7: =IF(G7="","",IF(G7="NA","_",G7+(F7*365)))
A8: Incendie | B8: Désenfumage | C8: Agence | E8: NON | F8: 1 | J8: =IF(E8="Non","",IF(H8=0,"NA",H8-I8)) | L8: =IF(G8="","",IF(G8="NA","_",G8+(F8*365)))
A9: Incendie | B9: Colonnes Sèches | C9: Agence | E9: NON | F9: 1 | J9: =IF(E9="Non","",IF(H9=0,"NA",H9-I9)) | L9: =IF(G9="","",IF(G9="NA","_",G9+(F9*365)))
A10: Incendie | B10: Poteaux Incendie | C10: Agence | E10: NON | F10: 1 | J10: =IF(E10="Non","",IF(H10=0,"NA",H10-I10)) | L10: =IF(G10="","",IF(G10="NA","_",G10+(F10*365)))
A11: Incendie | B11: Alarme Incendie | C11: Agence | E11: NON | F11: 1 | J11: =IF(E11="Non","",IF(H11=0,"NA",H11-I11)) | L11: =IF(G11="","",IF(G11="NA","_",G11+(F11*365)))
A12: Incendie | B12: Exercice d'Evacuation | C12: Agence | E12: NON | F12: 0.5 | J12: =IF(E12="Non","",IF(H12=0,"NA",H12-I12)) | L12: =IF(G12="","",IF(G12="NA","_",G12+(F12*365)))
A13: Registres Réglementaires | B13: Document Unique | C13: Agence | E13: NON | F13: 1 | J13: =IF(E13="Non","",IF(H13=0,"NA",H13-I13)) | L13: =IF(G13="","",IF(G13="NA","_",G13+(F13*365)))
A14: Registres Réglementaires | B14: Alerte sur Dangers Graves et Imminents | C14: Agence | E14: NON | F14: 1 | J14: =IF(E14="Non","",IF(H14=0,"NA",H14-I14)) | L14: =IF(G14="","",IF(G14="NA","_",G14+(F14*365)))
A15: Registres Réglementaires | B15: Alerte Santé Publique et Environnement | C15: Agence | E15: NON | F15: 1 | J15: =IF(E15="Non","",IF(H15=0,"NA",H15-I15)) | L15: =IF(G15="","",IF(G15="NA","_",G15+(F15*365)))
... A93: Divers | B93: Détecteurs gaz aérothermes | C93: Magasin | E93: NON | F93: 1 | J93: =IF(E93="Non","",IF(H93=0,"NA",H93-I93)) | L93: =IF(G93="","",IF(G93="NA","_",G93+(F93*365)))

Sheet Gestion nouveaux
A1: Suivi de l'accueil des nouveaux arrivants
A2: N° | B2: Date d'arrivée | C2: Nom Prénom | D2: Activité | E2: Fonction | F2: Statut | G2: Fiche de recensement des besoins | H2: Fiche d'aptitude médicale | I2: Date de la visite terrain par manager | K2: Suivi de l'accueil - Modules à réaliser | Z2: Nombre de jours depuis son arrivée | AA2: Base EHS | AB2: date du départ du collaborateur
K3: 1er jour | L3: 1er jour | M3: <30j | N3: <30j | O3: <30j | P3: <30j | Q3: <30j | R3: <30j ou <90j | S3: <90j | T3: <90j | U3: <30j | V3: <30j | W3: <6mois | X3: <30j | Y3: <30j
I4: Date maximale de réalisation de la visite | J4: Date effective de réalisation | K4: Tronc Commun | L4: Technicien | M4: Travaux en Hauteur Echelles et escabeaux | N4: Travaux en Hauteur Nacelle | O4: Risque Electrique | P4: Port des EPI | Q4: Organisation EHS | R4: Risque Routier | S4: Equipement sous Pression | T4: Espaces Confinés | U4: Désenfumage | V4: Analyse des risques | W4: Fondamentaux Sécurité | X4: Gestes et Postures | Y4: Organisation des stocks
A5: 1 | I5: =IF(B5="","",B5+30) | Z5: =IF(ISBLANK(C5),"",(IF(F5<>"CDI",TODAY()-B5,""))) | AA5: =IF(Z5="","",(IF(Z5>89,"Ajouter ce collaborateur dans la base EHS","")))
A6: 2 | I6: =IF(B6="","",B6+30) | Z6: =IF(ISBLANK(C6),"",(IF(F6<>"CDI",TODAY()-B6,""))) | AA6: =IF(Z6="","",(IF(Z6>89,"Ajouter ce collaborateur dans la base EHS","")))
A7: 3 | I7: =IF(B7="","",B7+30) | Z7: =IF(ISBLANK(C7),"",(IF(F7<>"CDI",TODAY()-B7,""))) | AA7: =IF(Z7="","",(IF(Z7>89,"Ajouter ce collaborateur dans la base EHS","")))
A8: 4 | I8: =IF(B8="","",B8+30) | Z8: =IF(ISBLANK(C8),"",(IF(F8<>"CDI",TODAY()-B8,""))) | AA8: =IF(Z8="","",(IF(Z8>89,"Ajouter ce collaborateur dans la base EHS","")))
A9: 5 | I9: =IF(B9="","",B9+30) | Z9: =IF(ISBLANK(C9),"",(IF(F9<>"CDI",TODAY()-B9,""))) | AA9: =IF(Z9="","",(IF(Z9>89,"Ajouter ce collaborateur dans la base EHS","")))
A10: 6 | I10: =IF(B10="","",B10+30) | Z10: =IF(ISBLANK(C10),"",(IF(F10<>"CDI",TODAY()-B10,""))) | AA10: =IF(Z10="","",(IF(Z10>89,"Ajouter ce collaborateur dans la base EHS","")))
A11: 7 | I11: =IF(B11="","",B11+30) | Z11: =IF(ISBLANK(C11),"",(IF(F11<>"CDI",TODAY()-B11,""))) | AA11: =IF(Z11="","",(IF(Z11>89,"Ajouter ce collaborateur dans la base EHS","")))
A12: 8 | I12: =IF(B12="","",B12+30) | Z12: =IF(ISBLANK(C12),"",(IF(F12<>"CDI",TODAY()-B12,""))) | AA12: =IF(Z12="","",(IF(Z12>89,"Ajouter ce collaborateur dans la base EHS","")))
A13: 9 | I13: =IF(B13="","",B13+30) | Z13: =IF(ISBLANK(C13),"",(IF(F13<>"CDI",TODAY()-B13,""))) | AA13: =IF(Z13="","",(IF(Z13>89,"Ajouter ce collaborateur dans la base EHS","")))
A14: 10 | I14: =IF(B14="","",B14+30) | Z14: =IF(ISBLANK(C14),"",(IF(F14<>"CDI",TODAY()-B14,""))) | AA14: =IF(Z14="","",(IF(Z14>89,"Ajouter ce collaborateur dans la base EHS","")))
A15: 11 | I15: =IF(B15="","",B15+30) | Z15: =IF(ISBLANK(C15),"",(IF(F15<>"CDI",TODAY()-B15,""))) | AA15: =IF(Z15="","",(IF(Z15>89,"Ajouter ce collaborateur dans la base EHS","")))
A16: 12 | I16: =IF(B16="","",B16+30) | Z16: =IF(ISBLANK(C16),"",(IF(F16<>"CDI",TODAY()-B16,""))) | AA16: =IF(Z16="","",(IF(Z16>89,"Ajouter ce collaborateur dans la base EHS","")))
... A34: 30 | I34: =IF(B34="","",B34+30) | Z34: =IF(ISBLANK(C34),"",(IF(F34<>"CDI",TODAY()-B34,""))) | AA34: =IF(Z34="","",(IF(Z34>89,"Ajouter ce collaborateur dans la base EHS","")))
B35: =COUNTA(B5:B34) -> 0 | L35: =COUNTA(L5:L34) -> 0

Sheet Gestion Sous-traitants
A1: Suivi des SOUS TRAITANT
A3: Type d'agence : | C3: Services | E3: Niveau 1 | F3: Travaux Dangereux (Travaux en hauteur à plus de 3m, raccordements électriques, extinction automatique, espaces confinés, poteaux incendie)
C4: =IF(C3="Installation (Chantier)",'Données (ne pas toucher)'!J20,'Données (ne pas toucher)'!J21) -> 3 audits niveau 1 1 audit niveau 2 Audits niveau 3 si pas assez de niveau 1 ou niveau 2 | E4: Niveau 2 | F4: Travaux hors travaux dangereux (tirage de câbles sans raccordement électrique, visite de maintenance, pose d'extincteurs, pose de RIA…)
E5: Niveau 3 | F5: Prestataires intervenant en agence (nettoyage bâtiments, contrôles périodiques…)
A7: N° | B7: Localisation | C7: Société sous-traitante | D7: Activité | F7: Nom de l'Affaire | G7: Visite terrain
D8: Type d'activité | E8: Decription (Chantier Désenfumage, chantier BAES, chantier Extincteur, chantier RIA, électricité…) | G8: Date | H8: Par qui | I8: Actions à solder ? | J8: Commentaires et/ou liste des actions
A9: 1
A10: 2
A11: 3
A12: 4
A13: 5
A14: 6
A15: 7
A16: 8
A17: 9
A18: 10
A19: 11
A20: 12
G21: =COUNTA(G9:G20) -> 0

Sheet Audit Eqpt Pression
A1: Suivi des audits des installations extinction automatique
A3: Toute nouvelle installation d'extinction automatique doit être auditée au cours du chantier à l'aide du document d'audit dédié - Audit Extinction Automatique FOR FS 022
A4: N° | B4: Nom de l'Affaire | C4: Type de gaz | D4: Nombre de bouteilles | E4: Présence sous-traitants | G4: Visite terrain
E5: ? | F5: Nom du sous-traitant | G5: Date | H5: Par qui | I5: Nom du technicien | J5: Actions à solder ? | K5: Commentaires et/ou liste des actions
A6: 1
A7: 2
A8: 3
A9: 4
A10: 5
A11: 6
A12: 7
A13: 8
A14: 9
A15: 10
A16: 11
A17: 12
G18: =COUNTA(G6:G17) -> 0

Sheet Indicateurs Qualité
A1: ="Indicateurs Qualité - " &#REF! -> #REF!
A2: Date : | C2: =TODAY() -> 43503
A4: REPARTITION DES ACTIONS PAR ORIGINE | L4: REPARTITION DES ACTIONS QUALITE AGENCE (6M)
W6: MILIEU - liées à l'environnement de travail
M7: ='Calcul qualite (ne pas toucher)'!F2 -> #REF! | P7: ='Calcul qualite (ne pas toucher)'!F7 -> #REF! | S7: ='Calcul qualite (ne pas toucher)'!F5 -> #REF! | W7: METHODE - liées à la manière de travailler
W8: MAIN D'ŒUVRE - liées au comportement du personnel
W9: MATIERE - liées à la proprité physique du matériau
M10: ='Calcul qualite (ne pas toucher)'!F6 -> #REF! | P10: ='Calcul qualite (ne pas toucher)'!F3 -> #REF! | S10: ='Calcul qualite (ne pas toucher)'!F4 -> #REF! | W10: MATERIEL - liées à l'outillage
W11: MANAGEMENT - liées aux transferts d'infos et consignes
A16: REPARTITIONS PAR PROCESSUS | L16: AVANCEMENT DE LA MISE EN ŒUVRE DES ACTIONS QUALITE
L18: ='Calcul qualite (ne pas toucher)'!E18 -> Nombre total de dysfonctionnement / Amélioration du plan | Z18: ='Calcul qualite (ne pas toucher)'!F18 -> 0

Sheet Calcul qualite (ne pas toucher)
H1: rang | I1: Origine | J1: % | K1: nb
B2: AC | C2: {=SUM(IF('Suivi des actions Qualite-EHS'!#REF!=B2,IF('Suivi des actions Qualite-EHS'!#REF!<>"s",IF('Suivi des actions Qualite-EHS'!#REF!<>"e",1,0))))} -> #REF! | E2: Milieu | F2: {=SUM(IF('Suivi des actions Qualite-EHS'!#REF!=E2,IF('Suivi des actions Qualite-EHS'!#REF!<>"s",IF('Suivi des actions Qualite-EHS'!#REF!<>"e",1,0))))} -> #REF! | H2: =RANK(K2,$K$2:$K$28) -> #REF! | I2: ='Données (ne pas toucher)'!#REF! -> #REF! | J2: =K2/SUM($K$2:$K$28)*100 -> #REF! | K2: {=SUM(IF('Suivi des actions Qualite-EHS'!$D$14:$D$433=I2,IF('Suivi des actions Qualite-EHS'!#REF!<>"s",IF('Suivi des actions Qualite-EHS'!#REF!<>"e",1,0))))} -> #REF! | L2: =I2 & " " &J2 -> #REF! | M2: ='Données (ne pas toucher)'!#REF! -> #REF!
B3: AP | C3: {=SUM(IF('Suivi des actions Qualite-EHS'!#REF!=B3,IF('Suivi des actions Qualite-EHS'!#REF!<>"s",IF('Suivi des actions Qualite-EHS'!#REF!<>"e",1,0))))} -> #REF! | E3: Matériel | F3: {=SUM(IF('Suivi des actions Qualite-EHS'!#REF!=E3,IF('Suivi des actions Qualite-EHS'!#REF!<>"s",IF('Suivi des actions Qualite-EHS'!#REF!<>"e",1,0))))} -> #REF! | H3: =RANK(K3,$K$2:$K$28) -> #REF! | I3: ='Données (ne pas toucher)'!#REF! -> #REF! | J3: =K3/SUM($K$2:$K$28)*100 -> #REF! | K3: {=SUM(IF('Suivi des actions Qualite-EHS'!$D$14:$D$433=I3,IF('Suivi des actions Qualite-EHS'!#REF!<>"s",IF('Suivi des actions Qualite-EHS'!#REF!<>"e",1,0))))} -> #REF! | L3: =I3 & " " &J3 -> #REF! | M3: ='Données (ne pas toucher)'!#REF! -> #REF!
E4: Management | F4: {=SUM(IF('Suivi des actions Qualite-EHS'!#REF!=E4,IF('Suivi des actions Qualite-EHS'!#REF!<>"s",IF('Suivi des actions Qualite-EHS'!#REF!<>"e",1,0))))} -> #REF! | H4: =RANK(K4,$K$2:$K$28) -> #REF! | I4: ='Données (ne pas toucher)'!#REF! -> #REF! | J4: =K4/SUM($K$2:$K$28)*100 -> #REF! | K4: {=SUM(IF('Suivi des actions Qualite-EHS'!$D$14:$D$433=I4,IF('Suivi des actions Qualite-EHS'!#REF!<>"s",IF('Suivi des actions Qualite-EHS'!#REF!<>"e",1,0))))} -> #REF! | L4: =I4 & " " &J4 -> #REF! | M4: ='Données (ne pas toucher)'!#REF! -> #REF!
E5: Main d'œuvre | F5: {=SUM(IF('Suivi des actions Qualite-EHS'!#REF!=E5,IF('Suivi des actions Qualite-EHS'!#REF!<>"s",IF('Suivi des actions Qualite-EHS'!#REF!<>"e",1,0))))} -> #REF! | H5: =RANK(K5,$K$2:$K$28) -> #REF! | I5: ='Données (ne pas toucher)'!#REF! -> #REF! | J5: =K5/SUM($K$2:$K$28)*100 -> #REF! | K5: {=SUM(IF('Suivi des actions Qualite-EHS'!$D$14:$D$433=I5,IF('Suivi des actions Qualite-EHS'!#REF!<>"s",IF('Suivi des actions Qualite-EHS'!#REF!<>"e",1,0))))} -> #REF! | L5: =I5 & " " &J5 -> #REF! | M5: ='Données (ne pas toucher)'!#REF! -> #REF!
E6: Matière | F6: {=SUM(IF('Suivi des actions Qualite-EHS'!#REF!=E6,IF('Suivi des actions Qualite-EHS'!#REF!<>"s",IF('Suivi des actions Qualite-EHS'!#REF!<>"e",1,0))))} -> #REF! | H6: =RANK(K6,$K$2:$K$28) -> #REF! | I6: ='Données (ne pas toucher)'!#REF! -> #REF! | J6: =K6/SUM($K$2:$K$28)*100 -> #REF! | K6: {=SUM(IF('Suivi des actions Qualite-EHS'!$D$14:$D$433=I6,IF('Suivi des actions Qualite-EHS'!#REF!<>"s",IF('Suivi des actions Qualite-EHS'!#REF!<>"e",1,0))))} -> #REF! | L6: =I6 & " " &J6 -> #REF! | M6: ='Données (ne pas toucher)'!#REF! -> #REF!
E7: Méthodes | F7: {=SUM(IF('Suivi des actions Qualite-EHS'!#REF!=E7,IF('Suivi des actions Qualite-EHS'!#REF!<>"s",IF('Suivi des actions Qualite-EHS'!#REF!<>"e",1,0))))} -> #REF! | H7: =RANK(K7,$K$2:$K$28) -> #REF! | I7: ='Données (ne pas toucher)'!#REF! -> #REF! | J7: =K7/SUM($K$2:$K$28)*100 -> #REF! | K7: {=SUM(IF('Suivi des actions Qualite-EHS'!$D$14:$D$433=I7,IF('Suivi des actions Qualite-EHS'!#REF!<>"s",IF('Suivi des actions Qualite-EHS'!#REF!<>"e",1,0))))} -> #REF! | L7: =I7 & " " &J7 -> #REF! | M7: ='Données (ne pas toucher)'!#REF! -> #REF!
H8: =RANK(K8,$K$2:$K$28) -> #REF! | I8: ='Données (ne pas toucher)'!#REF! -> #REF! | J8: =K8/SUM($K$2:$K$28)*100 -> #REF! | K8: {=SUM(IF('Suivi des actions Qualite-EHS'!$D$14:$D$433=I8,IF('Suivi des actions Qualite-EHS'!#REF!<>"s",IF('Suivi des actions Qualite-EHS'!#REF!<>"e",1,0))))} -> #REF! | L8: =I8 & " " &J8 -> #REF! | M8: ='Données (ne pas toucher)'!#REF! -> #REF!
H9: =RANK(K9,$K$2:$K$28) -> #REF! | I9: ='Données (ne pas toucher)'!#REF! -> #REF! | J9: =K9/SUM($K$2:$K$28)*100 -> #REF! | K9: {=SUM(IF('Suivi des actions Qualite-EHS'!$D$14:$D$433=I9,IF('Suivi des actions Qualite-EHS'!#REF!<>"s",IF('Suivi des actions Qualite-EHS'!#REF!<>"e",1,0))))} -> #REF! | L9: =I9 & " " &J9 -> #REF! | M9: ='Données (ne pas toucher)'!#REF! -> #REF!
E10: Répartition par Processus | H10: =RANK(K10,$K$2:$K$28) -> #REF! | I10: ='Données (ne pas toucher)'!#REF! -> #REF! | J10: =K10/SUM($K$2:$K$28)*100 -> #REF! | K10: {=SUM(IF('Suivi des actions Qualite-EHS'!$D$14:$D$433=I10,IF('Suivi des actions Qualite-EHS'!#REF!<>"s",IF('Suivi des actions Qualite-EHS'!#REF!<>"e",1,0))))} -> #REF! | L10: =I10 & " " &J10 -> #REF! | M10: ='Données (ne pas toucher)'!#REF! -> #REF!
C11: Management/ Pilotage | E11: ='Données (ne pas toucher)'!#REF! -> #REF! | F11: {=SUM(IF('Suivi des actions Qualite-EHS'!#REF!=E11,1,0))} -> #REF! | H11: =RANK(K11,$K$2:$K$28) -> #REF! | I11: ='Données (ne pas toucher)'!#REF! -> #REF! | J11: =K11/SUM($K$2:$K$28)*100&"%" -> #REF! | K11: {=SUM(IF('Suivi des actions Qualite-EHS'!$D$14:$D$433=I11,IF('Suivi des actions Qualite-EHS'!#REF!<>"s",IF('Suivi des actions Qualite-EHS'!#REF!<>"e",1,0))))} -> #REF! | L11: =I11 & " " &J11 -> #REF! | M11: ='Données (ne pas toucher)'!#REF! -> #REF!
C12: Vente | E12: ='Données (ne pas toucher)'!#REF! -> #REF! | F12: {=SUM(IF('Suivi des actions Qualite-EHS'!#REF!=E12,1,0))} -> #REF! | H12: =RANK(K12,$K$2:$K$28) -> #REF! | I12: ='Données (ne pas toucher)'!#REF! -> #REF! | J12: =K12/SUM($K$2:$K$28)*100&"%" -> #REF! | K12: {=SUM(IF('Suivi des actions Qualite-EHS'!$D$14:$D$433=I12,IF('Suivi des actions Qualite-EHS'!#REF!<>"s",IF('Suivi des actions Qualite-EHS'!#REF!<>"e",1,0))))} -> #REF! | L12: =I12 & " " &J12 -> #REF! | M12: ='Données (ne pas toucher)'!#REF! -> #REF!
C13: Installation | E13: ='Données (ne pas toucher)'!#REF! -> #REF! | F13: {=SUM(IF('Suivi des actions Qualite-EHS'!#REF!=E13,1,0))} -> #REF! | H13: =RANK(K13,$K$2:$K$28) -> #REF! | I13: ='Données (ne pas toucher)'!#REF! -> #REF! | J13: =K13/SUM($K$2:$K$28)*100&"%" -> #REF! | K13: {=SUM(IF('Suivi des actions Qualite-EHS'!$D$14:$D$433=I13,IF('Suivi des actions Qualite-EHS'!#REF!<>"s",IF('Suivi des actions Qualite-EHS'!#REF!<>"e",1,0))))} -> #REF! | L13: =I13 & " " &J13 -> #REF! | M13: ='Données (ne pas toucher)'!#REF! -> #REF!
C14: Service/ Installation | E14: ='Données (ne pas toucher)'!#REF! -> #REF! | F14: {=SUM(IF('Suivi des actions Qualite-EHS'!#REF!=E14,1,0))} -> #REF! | H14: =RANK(K14,$K$2:$K$28) -> #REF! | I14: ='Données (ne pas toucher)'!#REF! -> #REF! | J14: =K14/SUM($K$2:$K$28)*100&"%" -> #REF! | K14: {=SUM(IF('Suivi des actions Qualite-EHS'!$D$14:$D$433=I14,IF('Suivi des actions Qualite-EHS'!#REF!<>"s",IF('Suivi des actions Qualite-EHS'!#REF!<>"e",1,0))))} -> #REF! | L14: =I14 & " " &J14 -> #REF! | M14: ='Données (ne pas toucher)'!#REF! -> #REF!
C15: Support (RH, HA, Matériel..) | E15: ='Données (ne pas toucher)'!#REF! -> #REF! | F15: {=SUM(IF('Suivi des actions Qualite-EHS'!#REF!=E15,1,0))} -> #REF! | H15: =RANK(K15,$K$2:$K$28) -> #REF! | I15: ='Données (ne pas toucher)'!#REF! -> #REF! | J15: =K15/SUM($K$2:$K$28)*100&"%" -> #REF! | K15: {=SUM(IF('Suivi des actions Qualite-EHS'!$D$14:$D$433=I15,IF('Suivi des actions Qualite-EHS'!#REF!<>"s",IF('Suivi des actions Qualite-EHS'!#REF!<>"e",1,0))))} -> #REF! | L15: =I15 & " " &J15 -> #REF! | M15: ='Données (ne pas toucher)'!#REF! -> #REF!
H16: =RANK(K16,$K$2:$K$28) -> #REF! | I16: ='Données (ne pas toucher)'!#REF! -> #REF! | J16: =K16/SUM($K$2:$K$28)*100&"%" -> #REF! | K16: {=SUM(IF('Suivi des actions Qualite-EHS'!$D$14:$D$433=I16,IF('Suivi des actions Qualite-EHS'!#REF!<>"s",IF('Suivi des actions Qualite-EHS'!#REF!<>"e",1,0))))} -> #REF! | L16: =I16 & " " &J16 -> #REF! | M16: ='Données (ne pas toucher)'!#REF! -> #REF!
H17: =RANK(K17,$K$2:$K$28) -> #REF! | I17: ='Données (ne pas toucher)'!#REF! -> #REF! | J17: =K17/SUM($K$2:$K$28)*100&"%" -> #REF! | K17: {=SUM(IF('Suivi des actions Qualite-EHS'!$D$14:$D$433=I17,IF('Suivi des actions Qualite-EHS'!#REF!<>"s",IF('Suivi des actions Qualite-EHS'!#REF!<>"e",1,0))))} -> #REF! | L17: =I17 & " " &J17 -> #REF! | M17: ='Données (ne pas toucher)'!#REF! -> #REF!
E18: Nombre total de dysfonctionnement / Amélioration du plan | F18: {=SUM(IF('Suivi des actions Qualite-EHS'!$E$14:$E$433<>"",IF('Suivi des actions Qualite-EHS'!#REF!<>"s",IF('Suivi des actions Qualite-EHS'!#REF!<>"e",1,0))))} -> 0 | H18: =RANK(K18,$K$2:$K$28) -> #REF! | I18: ='Données (ne pas toucher)'!#REF! -> #REF! | J18: =K18/SUM($K$2:$K$28)*100&"%" -> #REF! | K18: {=SUM(IF('Suivi des actions Qualite-EHS'!$D$14:$D$433=I18,IF('Suivi des actions Qualite-EHS'!#REF!<>"s",IF('Suivi des actions Qualite-EHS'!#REF!<>"e",1,0))))} -> #REF! | L18: =I18 & " " &J18 -> #REF! | M18: ='Données (ne pas toucher)'!#REF! -> #REF!
E19: Nombre d'actions définies | F19: {=SUM(IF('Suivi des actions Qualite-EHS'!$J$14:$J$433<>"",IF('Suivi des actions Qualite-EHS'!#REF!<>"s",IF('Suivi des actions Qualite-EHS'!#REF!<>"e",1,0))))} -> 0 | H19: =RANK(K19,$K$2:$K$28) -> #REF! | I19: ='Données (ne pas toucher)'!#REF! -> #REF! | J19: =K19/SUM($K$2:$K$28)*100&"%" -> #REF! | K19: {=SUM(IF('Suivi des actions Qualite-EHS'!$D$14:$D$433=I19,IF('Suivi des actions Qualite-EHS'!#REF!<>"s",IF('Suivi des actions Qualite-EHS'!#REF!<>"e",1,0))))} -> #REF! | L19: =I19 & " " &J19 -> #REF! | M19: ='Données (ne pas toucher)'!#REF! -> #REF!
E20: Taux d'actions définies | F20: =F19*100/F18 -> #DIV/0! | G20: % | H20: =RANK(K20,$K$2:$K$28) -> #REF! | I20: ='Données (ne pas toucher)'!#REF! -> #REF! | J20: =K20/SUM($K$2:$K$28)*100&"%" -> #REF! | K20: {=SUM(IF('Suivi des actions Qualite-EHS'!$D$14:$D$433=I20,IF('Suivi des actions Qualite-EHS'!#REF!<>"s",IF('Suivi des actions Qualite-EHS'!#REF!<>"e",1,0))))} -> #REF! | L20: =I20 & " " &J20 -> #REF! | M20: ='Données (ne pas toucher)'!#REF! -> #REF!
E21: Taux d'avancement | F21: =SUMIF('Suivi des actions Qualite-EHS'!#REF!,"q*",'Suivi des actions Qualite-EHS'!$N$14:$N$433)*100/F18 -> #REF! | G21: % | H21: =RANK(K21,$K$2:$K$28) -> #REF! | I21: ='Données (ne pas toucher)'!#REF! -> #REF! | J21: =K21/SUM($K$2:$K$28)*100&"%" -> #REF! | K21: {=SUM(IF('Suivi des actions Qualite-EHS'!$D$14:$D$433=I21,IF('Suivi des actions Qualite-EHS'!#REF!<>"s",IF('Suivi des actions Qualite-EHS'!#REF!<>"e",1,0))))} -> #REF! | L21: =I21 & " " &J21 -> #REF! | M21: ='Données (ne pas toucher)'!#REF! -> #REF!
E22: Taux Soldé/Nb de dysfonctionnements | F22: =F25/F18*100 -> #DIV/0! | G22: % | H22: =RANK(K22,$K$2:$K$28) -> #REF! | I22: ='Données (ne pas toucher)'!#REF! -> #REF! | J22: =K22/SUM($K$2:$K$28)*100&"%" -> #REF! | K22: {=SUM(IF('Suivi des actions Qualite-EHS'!$D$14:$D$433=I22,IF('Suivi des actions Qualite-EHS'!#REF!<>"s",IF('Suivi des actions Qualite-EHS'!#REF!<>"e",1,0))))} -> #REF! | L22: =I22 & " " &J22 -> #REF! | M22: ='Données (ne pas toucher)'!#REF! -> #REF!
E23: Taux de vérification d'efficacité/ Soldés | F23: =F26*100/F25 -> #DIV/0! | G23: % | H23: =RANK(K23,$K$2:$K$28) -> #REF! | I23: ='Données (ne pas toucher)'!#REF! -> #REF! | J23: =K23/SUM($K$2:$K$28)*100&"%" -> #REF! | K23: {=SUM(IF('Suivi des actions Qualite-EHS'!$D$14:$D$433=I23,IF('Suivi des actions Qualite-EHS'!#REF!<>"s",IF('Suivi des actions Qualite-EHS'!#REF!<>"e",1,0))))} -> #REF! | L23: =I23 & " " &J23 -> #REF! | M23: ='Données (ne pas toucher)'!#REF! -> #REF!
E24: Taux de vérification d'efficacité/ Total | F24: =F26*100/F18 -> #DIV/0! | G24: % | H24: =RANK(K24,$K$2:$K$28) -> #REF! | I24: ='Données (ne pas toucher)'!#REF! -> #REF! | J24: =K24/SUM($K$2:$K$28)*100&"%" -> #REF! | K24: {=SUM(IF('Suivi des actions Qualite-EHS'!$D$14:$D$433=I24,IF('Suivi des actions Qualite-EHS'!#REF!<>"s",IF('Suivi des actions Qualite-EHS'!#REF!<>"e",1,0))))} -> #REF! | L24: =I24 & " " &J24 -> #REF! | M24: ='Données (ne pas toucher)'!#REF! -> #REF!
E25: nb de solde | F25: {=SUM(IF('Suivi des actions Qualite-EHS'!$N$14:$N$433=1,IF('Suivi des actions Qualite-EHS'!#REF!<>"s",IF('Suivi des actions Qualite-EHS'!#REF!<>"e",1,0))))} -> 0 | H25: =RANK(K25,$K$2:$K$28) -> #REF! | I25: ='Données (ne pas toucher)'!#REF! -> #REF! | J25: =K25/SUM($K$2:$K$28)*100&"%" -> #REF! | K25: {=SUM(IF('Suivi des actions Qualite-EHS'!$D$14:$D$433=I25,IF('Suivi des actions Qualite-EHS'!#REF!<>"s",IF('Suivi des actions Qualite-EHS'!#REF!<>"e",1,0))))} -> #REF! | L25: =I25 & " " &J25 -> #REF! | M25: ='Données (ne pas toucher)'!#REF! -> #REF!
E26: nb efficace non vide | F26: {=SUM(IF('Suivi des actions Qualite-EHS'!$N$14:$N$433=1,IF('Suivi des actions Qualite-EHS'!#REF!<>"",IF('Suivi des actions Qualite-EHS'!#REF!<>"s",IF('Suivi des actions Qualite-EHS'!#REF!<>"e",1,0)))))} -> 0 | H26: =RANK(K26,$K$2:$K$28) -> #REF! | I26: ='Données (ne pas toucher)'!#REF! -> #REF! | J26: =K26/SUM($K$2:$K$28)*100&"%" -> #REF! | K26: {=SUM(IF('Suivi des actions Qualite-EHS'!$D$14:$D$433=I26,IF('Suivi des actions Qualite-EHS'!#REF!<>"s",IF('Suivi des actions Qualite-EHS'!#REF!<>"e",1,0))))} -> #REF! | L26: =I26 & " " &J26 -> #REF! | M26: ='Données (ne pas toucher)'!#REF! -> #REF!
H27: =RANK(K27,$K$2:$K$28) -> #REF! | I27: ='Données (ne pas toucher)'!#REF! -> #REF! | J27: =K27/SUM($K$2:$K$28)*100&"%" -> #REF! | K27: {=SUM(IF('Suivi des actions Qualite-EHS'!$D$14:$D$433=I27,IF('Suivi des actions Qualite-EHS'!#REF!<>"s",IF('Suivi des actions Qualite-EHS'!#REF!<>"e",1,0))))} -> #REF! | L27: =I27 & " " &J27 -> #REF! | M27: ='Données (ne pas toucher)'!#REF! -> #REF!
H28: =RANK(K28,$K$2:$K$28) -> #REF! | I28: ='Données (ne pas toucher)'!#REF! -> #REF! | J28: =K28/SUM($K$2:$K$28)*100&"%" -> #REF! | K28: {=SUM(IF('Suivi des actions Qualite-EHS'!$D$14:$D$433=I28,IF('Suivi des actions Qualite-EHS'!#REF!<>"s",IF('Suivi des actions Qualite-EHS'!#REF!<>"e",1,0))))} -> #REF! | L28: =I28 & " " &J28 -> #REF! | M28: ='Données (ne pas toucher)'!#REF! -> #REF!

Sheet Données (ne pas toucher)
O1: Fonctions | P1: Service | Q1: Agence | R1: Etablissement
A2: Déchets | B2: Travail en hauteur | C2: 1 - Bénin | F2: Haute | G2: CDI | H2: Q1 | I2: Oui | J2: ATAA | L2: Oui | M2: Causerie Q1 | N2: Accident | O2: Animateur APV | P2: Administratif | Q2: Dijon-Reims | R2: DIJON
A3: Document | B3: Risque électrique | C3: 2 - AT sans Arrêt | F3: Autre | G3: CDD | H3: Q2 | I3: Non | J3: ATSA | L3: Non | M3: Causerie Q2 | N3: Accident bénin | O3: Animateur Région | P3: Désenfumage | Q3: Nancy_Strasbourg | R3: REIMS
A4: Electrique | B4: Energies dangereuses | C4: 3 - AT avec Arrêt | G4: Intérim | H4: Q3 | I4: Fait | J4: PS | L4: Fait le | M4: Causerie Q3 | N4: Accueil EHS | O4: Assistante Etablissement | P4: Direction | R4: NANCY
A5: EPI | B5: Espaces confinés | C5: 4 - Irréversible ou mortelle | G5: Stagiaire | H5: Q4 | J5: ATJAA | M5: Causerie Q4 | N5: APSAD | O5: Assistante Régionale | P5: Formation CCF | R5: STRASBOURG
A6: Formation | B6: Charges suspendues | C6: 1 - Mauvais tri déchets | G6: Contrat Pro | H6: NA | J6: ATJSA | N6: Audit de management | O6: BE | P6: Réalisation | R6: 2 Etablissements
A7: Hauteur | B7: Chariots élevateurs | C7: 2 - Renversement produit | N7: Audit externe | O7: Chargé d'affaires | P7: SAV Chubb
A8: Indicateur | B8: Risque routier | C8: 3 - Percussion accidentelle de réservoirs fluorés | N8: Audit interne | O8: Commercial | P8: SAV Sicli
A9: Outillages | B9: Machines | C9: 4 - Incendie | N9: Autre audit | O9: Directeur d'Agence | P9: Ventes Chubb
A10: Produit chimique | B10: Engins | N10: Causerie | O10: Fifty | P10: Ventes Sicli
A11: Véhicule | B11: EPI | N11: CE/DP | O11: Formateur
B12: Outillages | N12: CHSCT | O12: Gestionnaire stock
B13: Chute de plain-pied | N13: Client / Plainte | O13: Poseur
A14: Administratif | B14: Produits chimiques | H14: Niveau 1 | I14: Installation (Chantier) | N14: Comité EHS agence | O14: Responsable Administratif
A15: Gestionnaire de stocks | B15: Amiante | E15: Circulation | F15: Choc arrière | H15: Niveau 2 | I15: Services | N15: Comité EHS national | O15: Responsable Réa
A16: Directeur d'Agence | B16: Déchets | E16: Manœuvre | F16: Choc avant | H16: Niveau 3 | N16: Comité EHS régional | O16: Responsable Désenfumage
A17: Encadrant | B17: Réservoirs sous pression | E17: Stationnement | F17: Choc avec animal | N17: Evaluation des risques | O17: Responsable Ventes
A18: Commercial | B18: Stockage | E18: Non rempli | F18: Choc contre obstacle fixe | N18: Exercices | O18: RST
A19: Technicien | B19: Inspections périodiques | E19: NA | F19: Choc côté | N19: Formation | O19: Spéc. BAES
B20: 5S | F20: Choc en croisant | I20: Installation | J20: 8 audits niveau 1 2 audits niveau 2 Audits niveau 3 si pas assez de niveau 1 ou niveau 2 | N20: Information groupe | O20: Spéc. RIA
B21: Sous-Traitance | F21: Choc en dépassement | I21: Services | J21: 3 audits niveau 1 1 audit niveau 2 Audits niveau 3 si pas assez de niveau 1 ou niveau 2 | N21: Inspection mensuelle | O21: TAPV Désenf.
B22: Documentaire | F22: Chute d'objet | N22: MFA/réclamation client | O22: Technicien MES
B23: Divers | F23: Collision en chaine | N23: Plan de prévention / FAR | O23: Technicien SAV
F24: Non rempli | N24: Presqu'accident | O24: Assistante
F25: Perte de contrôle | N25: Réglementaire | O25: Autre
A26: Env | B26: Main d'œuvre | C26: AC | F26: Piéton | N26: Remontée terrain
A27: Q Installation | B27: Management | C27: AP | F27: Sans tiers identifié | N27: Reunion interne
A28: Q Management | B28: Matériel | C28: Pilotage | N28: Revue de Direction
A29: Q Service / Maintenance | B29: Matière | N29: Vérification périodique
A30: Q Support(RH, materiel ..) | B30: Méthodes | N30: Visite EHS/Qualité
A31: Q Vente | B31: Milieu
A32: Santé
A33: Séc
A35: 1 - Eviter le risque
A36: 2 - Evaluer le risque
A37: 3 - Combattre les risques à la source
A38: 4 - Adapter le travail
A39: 5 - Tenir compte de l'évolution de la technique
A40: 6 - Remplacer ce qui est dangereux
A41: 7 - Planifier la prévention
...

Sheet Calcul base
A1: AC | B1: =COUNTIF('Suivi des actions Qualite-EHS'!#REF!,"AC") -> #REF! | D1: Milieu | E1: =COUNTIF('Suivi des actions Qualite-EHS'!#REF!,D1) -> #REF! | G1: ='Données (ne pas toucher)'!#REF! -> #REF! | H1: =COUNTIF('Suivi des actions Qualite-EHS'!#REF!,G1) -> #REF! | I1: =H1/SUM($H$1:$H$26) -> #REF! | J1: =RANK(H1,$H$1:$H$26) -> #REF!
A2: AP | B2: =COUNTIF('Suivi des actions Qualite-EHS'!#REF!,"AP") -> #REF! | D2: Matériel | E2: =COUNTIF($I$7:$I$403,D2) -> 0 | G2: ='Données (ne pas toucher)'!#REF! -> #REF! | H2: =COUNTIF('Suivi des actions Qualite-EHS'!#REF!,G2) -> #REF! | I2: =H2/SUM($H$1:$H$26) -> #REF! | J2: =RANK(H2,$H$1:$H$26) -> #REF!
D3: Management | E3: =COUNTIF('Suivi des actions Qualite-EHS'!#REF!,D3) -> #REF! | G3: ='Données (ne pas toucher)'!#REF! -> #REF! | H3: =COUNTIF('Suivi des actions Qualite-EHS'!#REF!,G3) -> #REF! | I3: =H3/SUM($H$1:$H$26) -> #REF! | J3: =RANK(H3,$H$1:$H$26) -> #REF!
D4: Main d'œuvre | E4: =COUNTIF('Suivi des actions Qualite-EHS'!#REF!,D4) -> #REF! | G4: ='Données (ne pas toucher)'!#REF! -> #REF! | H4: =COUNTIF('Suivi des actions Qualite-EHS'!#REF!,G4) -> #REF! | I4: =H4/SUM($H$1:$H$26) -> #REF! | J4: =RANK(H4,$H$1:$H$26) -> #REF!
D5: Matière | E5: =COUNTIF('Suivi des actions Qualite-EHS'!#REF!,D5) -> #REF! | G5: ='Données (ne pas toucher)'!#REF! -> #REF! | H5: =COUNTIF('Suivi des actions Qualite-EHS'!#REF!,G5) -> #REF! | I5: =H5/SUM($H$1:$H$26) -> #REF! | J5: =RANK(H5,$H$1:$H$26) -> #REF!
D6: Méthodes | E6: =COUNTIF('Suivi des actions Qualite-EHS'!#REF!,D6) -> #REF! | G6: ='Données (ne pas toucher)'!#REF! -> #REF! | H6: =COUNTIF('Suivi des actions Qualite-EHS'!#REF!,G6) -> #REF! | I6: =H6/SUM($H$1:$H$26) -> #REF! | J6: =RANK(H6,$H$1:$H$26) -> #REF!
G7: ='Données (ne pas toucher)'!#REF! -> #REF! | H7: =COUNTIF('Suivi des actions Qualite-EHS'!#REF!,G7) -> #REF! | I7: =H7/SUM($H$1:$H$26) -> #REF! | J7: =RANK(H7,$H$1:$H$26) -> #REF!
G8: ='Données (ne pas toucher)'!#REF! -> #REF! | H8: =COUNTIF('Suivi des actions Qualite-EHS'!#REF!,G8) -> #REF! | I8: =H8/SUM($H$1:$H$26) -> #REF! | J8: =RANK(H8,$H$1:$H$26) -> #REF!
G9: ='Données (ne pas toucher)'!#REF! -> #REF! | H9: =COUNTIF('Suivi des actions Qualite-EHS'!#REF!,G9) -> #REF! | I9: =H9/SUM($H$1:$H$26) -> #REF! | J9: =RANK(H9,$H$1:$H$26) -> #REF!
G10: ='Données (ne pas toucher)'!#REF! -> #REF! | H10: =COUNTIF('Suivi des actions Qualite-EHS'!#REF!,G10) -> #REF! | I10: =H10/SUM($H$1:$H$26) -> #REF! | J10: =RANK(H10,$H$1:$H$26) -> #REF!
G11: ='Données (ne pas toucher)'!#REF! -> #REF! | H11: =COUNTIF('Suivi des actions Qualite-EHS'!#REF!,G11) -> #REF! | I11: =H11/SUM($H$1:$H$26) -> #REF! | J11: =RANK(H11,$H$1:$H$26) -> #REF!
G12: ='Données (ne pas toucher)'!#REF! -> #REF! | H12: =COUNTIF('Suivi des actions Qualite-EHS'!#REF!,G12) -> #REF! | I12: =H12/SUM($H$1:$H$26) -> #REF! | J12: =RANK(H12,$H$1:$H$26) -> #REF!
G13: ='Données (ne pas toucher)'!#REF! -> #REF! | H13: =COUNTIF('Suivi des actions Qualite-EHS'!#REF!,G13) -> #REF! | I13: =H13/SUM($H$1:$H$26) -> #REF! | J13: =RANK(H13,$H$1:$H$26) -> #REF!
G14: ='Données (ne pas toucher)'!#REF! -> #REF! | H14: =COUNTIF('Suivi des actions Qualite-EHS'!#REF!,G14) -> #REF! | I14: =H14/SUM($H$1:$H$26) -> #REF! | J14: =RANK(H14,$H$1:$H$26) -> #REF!
G15: ='Données (ne pas toucher)'!#REF! -> #REF! | H15: =COUNTIF('Suivi des actions Qualite-EHS'!#REF!,G15) -> #REF! | I15: =H15/SUM($H$1:$H$26) -> #REF! | J15: =RANK(H15,$H$1:$H$26) -> #REF!
G16: ='Données (ne pas toucher)'!#REF! -> #REF! | H16: =COUNTIF('Suivi des actions Qualite-EHS'!#REF!,G16) -> #REF! | I16: =H16/SUM($H$1:$H$26) -> #REF! | J16: =RANK(H16,$H$1:$H$26) -> #REF!
G17: ='Données (ne pas toucher)'!#REF! -> #REF! | H17: =COUNTIF('Suivi des actions Qualite-EHS'!#REF!,G17) -> #REF! | I17: =H17/SUM($H$1:$H$26) -> #REF! | J17: =RANK(H17,$H$1:$H$26) -> #REF!
G18: ='Données (ne pas toucher)'!#REF! -> #REF! | H18: =COUNTIF('Suivi des actions Qualite-EHS'!#REF!,G18) -> #REF! | I18: =H18/SUM($H$1:$H$26) -> #REF! | J18: =RANK(H18,$H$1:$H$26) -> #REF!
... G26: ='Données (ne pas toucher)'!#REF! -> #REF! | H26: =COUNTIF('Suivi des actions Qualite-EHS'!#REF!,G26) -> #REF! | I26: =H26/SUM($H$1:$H$26) -> #REF! | J26: =RANK(H26,$H$1:$H$26) -> #REF!
G27: ='Données (ne pas toucher)'!#REF! -> #REF!
G28: ='Données (ne pas toucher)'!#REF! -> #REF!
G29: ='Données (ne pas toucher)'!#REF! -> #REF!

Sheet Feuil1
