Workbook

Sheet Instruction
A1: Marche à suivre lorsqu’une affaire comprend une supervision à base de OPTIMA VISION :
A3: Attention, la mise en service sur site de la supervision dépend de l’environnement et des exigences du client, et est à estimer en complément.
A5: En phase chiffrage :
B6: 1 - Renseigner l'onglet "Besoin",
B7: 2 - Retourner ce document au format EXCEL uniquement à votre référent UAE | C7: Liste des référents
B9: Sous 15 jours, Votre référent UAE :
B10: 3 - Vous renverra par mail un document PDF résumant la liste des éléments à commander et le nombre d'heures de réalisation à prévoir,
B11: 4 - Créera un nouveau projet de supervision sur le site intranet « SiTech » accessible par l'IntraNews, en statut « chiffrage », | C11: http://cfrrya21/sitech/
B13: Vous devrez alors :
B14: 5 - Renseigner I-Sales avec la réponse fournie par votre Référent au point 3,
A16: Lors de la réception de la commande Client :
B17: 6 - Avertir votre référent UAE par email de l'obtention de la commande,
B18: 7 - Pour le matériel, lancer l'approvisionnement conformément à la liste fournie par votre Référent au point 3.
A20: En phase de réalisation:
B21: 8 - Le projet peut être réalisé en interne ou en externe auprès d'un prestataire référencé | C21: Liste des prestataires
A23: En phase de mise en service :
B24: 9 - Si une formation du personnel CHUBB a été prévue, se mettre en contact avec votre référent UAE pour planifier cette formation.
B25: 10 - L’assistance téléphonique sera assurée par votre Référent UAE en cas de besoin.

Sheet Besoin
D1: Recueil des besoins pour élaborer une supervision OPTIMA VISION | O1: Date :
A2: IMPR-3314 - 5
A4: RENSEIGNEMENTS GENERAUX
A6: Agence : | G6: Client : | M6: Site :
A8: Commercial : | G8: CAF / BE :
A11: INSTALLATION A SUPERVISER Nota: Les centrales référencées de la concurrence seront selectionnables dans une prochaine révision
A13: Installation déjà supervisée : | J13: =IF(H13="OUI"," -----> Avec quel logiciel :","")
A15: Centrales Chubb à superviser (quantité et type) :
A27: Y a-t-il un(des) site(s) distant(s) à superviser : | J27: =IF(H27="OUI"," ---> Combien de sites :","")
A28: Liaisons entre les SSI pour supervision :
A29: Commentaires sur liaison (nature, type, etc…) :
G30: Distances entre les divers matériels :
A32: ÖÖÖÖ Nota : Joindre un synoptique de l'architecture au format pdf ÕÕÕÕ
A34: GESTION DES PLANS
A36: Doit-on afficher des plans :
B38: =IF(E36="OUI"," ---> Combien de plans Autocad Clients à récupérer:","")
B39: =IF(E36="OUI"," ---> Combien de plans à afficher :","") | H39: =IF(E36="OUI","Limite à 100 symboles par synoptique","")
B40: =IF(E36="OUI"," ---> Des photos du site devront-elles apparaitre dans le projet :","") | M40: =IF(K40="Oui","--> Les récupérer chez le Client","")
A43: CONFIGURATION A PROPOSER
A45: Doit-on matérialiser les zones de détection ZD :
A47: =IF(H45="Oui","Doit-on matérialiser les pts de détection DA/DM :","")
A49: Doit-on matérialiser les DAS / DCT :
A51: =IF(H49="OUI","Graphique: un même plan doit-il contenir la DI et la Mise en sécurité ?","") | M51: =IF(K51="Non","Nb plans de Mise en Sec :","")
A53: Besoin option main courante : | L53: Besoin option SMS/Mail :
A55: Nombre de postes serveurs : | L55: =IF(H55>1,"Serveur redondant ? : ","")
A57: Nombre de postes Clients "LOURDS" : | O57: Nombre de postes Clients "LEGERS" :
A59: Doit-on fournir le(s) PC(s) : | K59: =IF(E59="OUI"," 680000080 - PC standard W7 64B ?","") | N59: =IF(AND(L59="NON",L61="NON"),"Veuillez commander PC et Ecran chez Arrow (138127)",IF(L59="NON","Veuillez commander le PC chez ARROW (138127)",IF(L61="NON","Veuillez commander l'Ecran chez ARROW (138127)","")))
A61: =IF(E59="OUI","Besoin d'écran :","") | K61: =IF(E61="OUI","680000081 - Ecran standard 24P ?","")
A64: CONFIGURATION A PROPOSER (suite…)
A66: Liaison poste serveur / poste(s) client(s) : | L66: =IF(H66="RESEAU ETHERNET CLIENT"," --> Comment est-il adressé :","")
A68: Une imprimante FIL DE L'EAU est-elle prévue : | J68: =IF(H68="OUI"," --> Qui doit la fournir :","")
A70: Une imprimante ECRAN est-elle prévue : | J70: =IF(H70="OUI"," --> Qui doit la fournir :","")
J72: =IF(AND(H70="Oui",M70="Chubb (Agence)")," --> Type","") | O72: =IF(L72="JET D'ENCRE", " --> Format :","")
A75: CALCUL LICENCES Optima Vision
F77: LON RESONANCE | H77: LON ACTIVA | J77: TOTAL
B78: Nombre de Centrale SDI | F78: =IF(C17="UTI.COM",B17) + IF(C19="UTI.COM",B19) + IF(C21="UTI.COM",B21) + IF(C23="UTI.COM",B23) + IF(C25="UTI.COM",B25)+IF(C17="UTC.COM",B17) + IF(C19="UTC.COM",B19) + IF(C21="UTC.COM",B21) + IF(C23="UTC.COM",B23) + IF(C25="UTC.COM",B25) -> 0 | H78: =IF(C17="ACTIVA 1000 LON",B17*22) + IF(C19="ACTIVA 1000 LON",B19*22) + IF(C21="ACTIVA 1000 LON",B21*22) + IF(C23="ACTIVA 1000 LON",B23*22) + IF(C25="ACTIVA 1000 LON",B25*22) -> 0 | J78: =SUM(F78:I78) -> 0 | P78: =J78+L78+N78+H78+F78 -> 0
B79: Nombre de Centrales CMSI | F79: =IF(C17="CMSI.COM",B17) + IF(C19="CMSI.COM",B19) + IF(C21="CMSI.COM",B21) + IF(C23="CMSI.COM",B23) + IF(C25="CMSI.COM",B25) -> 0 | H79: =IF(C17="ACTIVACOM LON",B17*15) + IF(C19="ACTIVACOM LON",B19*15) + IF(C21="ACTIVACOM LON",B21*15) + IF(C23="ACTIVACOM LON",B23*15) + IF(C25="ACTIVACOM LON",B25*15) -> 0 | J79: =SUM(F79:I79) -> 0 | P79: =J79+L79+N79+H79+F79 -> 0
B80: Nombre de Zones de détection | J80: =F80+(H80*2) -> 0
B81: Nombre de Points | J81: =F81+(H81*3) -> 0 | P81: =J81+L81+N81+H81+F81 -> 0
B82: Nombre de ZA / Fonctions | J82: =F82+(H82*9) -> 0 | P82: =J82+L82+N82+H82+F82 -> 0
...

Sheet Calcul
E1: Chiffrage OPTIMA VISION | L1: Réalisé par : | P1: Date :
A2: =Besoin!A2 -> IMPR-3314 - 5
A4: RENSEIGNEMENTS GENERAUX
A6: Agence : | D6: =Besoin!C6 -> 0 | H6: Client : | J6: =Besoin!I6 -> 0 | N6: Site : | O6: =Besoin!N6 -> 0
A7: Commercial : | D7: =Besoin!C8 -> 0 | H7: CAF / BE : | J7: =IF(Besoin!I8="","/",Besoin!I8) -> /
A10: LISTE DES MATERIELS NECESSAIRES
D12: Désignation | I12: Référence | N12: Quantité à prévoir | P12: Fournit par Client
C13: 1 | D13: PC | I13: =IF(Besoin!E59="OUI",IF(Besoin!L59="OUI","680000080 - PC Standard W10 64B",IF(Besoin!L59="NON","A commander chez Arrow (138127)","/")),IF(Besoin!E59="NON","PC W10-64b 8Go Ram SSD 128Go Raid1 ","/")) -> / | N13: =IF(Besoin!E59="OUI",Besoin!H55+Besoin!H57,IF(Besoin!E59="NON",Besoin!H55+Besoin!H57,"/")) -> / | P13: =IF(Besoin!E59="NON","OUI","/") -> /
C14: 2 | D14: Ecran | I14: =IF(Besoin!E59="OUI",IF(Besoin!L61="OUI","680000081 - Ecran Standard 24P",IF(Besoin!L61="NON","A commander chez Arrow (138127)","/")),IF(Besoin!E59="NON","Ecran 24 pouces 1920x1080px","/")) -> / | N14: =IF(Besoin!E61="OUI",Besoin!H55+Besoin!H57,IF(Besoin!E59="NON",Besoin!H55+Besoin!H57,"/")) -> / | P14: =IF(Besoin!E59="NON","OUI","/") -> /
C15: 3 | D15: Imprimante ECRAN | I15: =IF(Besoin!M70<>"CLIENT",Besoin!L72," ") -> 0 | M15: =IF(I15="JET D'ENCRE",Besoin!Q72,"") | N15: =IF(Besoin!H70="NON","/",IF(Besoin!M70="CHUBB (Agence)","1","/")) -> / | P15: =IF(Besoin!M70="CLIENT","OUI","/") -> /
C16: 4 | D16: Imprimante FIL DE L'EAU | I16: =IF(Besoin!M68="CHUBB (Epson LX300)","Epson LX 300","") | N16: =IF(Besoin!H68="NON","/",IF(Besoin!M68="CHUBB (Epson LX300)","1","/")) -> / | P16: =IF(Besoin!M68="CLIENT","OUI","/") -> /
C17: 5 | D17: Licence OPTIMA poste serveur | I17: =IF(Besoin!O84=0,"/",IF(Besoin!O84<120,"680000050 - OPTIMA UAE 150PTS",IF(Besoin!O84<250,"680000051 - OPTIMA UAE 300PTS",IF(Besoin!O84<400,"680000052 - OPTIMA UAE 500PTS",IF(Besoin!O84<800,"680000053 - OPTIMA UAE 1000PTS",IF(Besoin!O84<2000,"680000054 - OPTIMA UAE 2500PTS",IF(Besoin!O84<4000,"680000055 - OPTIMA VISION 5000PTS","680000056 - OPTIMA VISION 10000PTS"))))))) -> / | N17: =Besoin!H55 -> 0 | P17: /
C18: 6 | D18: Option Licence Supplémentaire | I18: =IF(Besoin!O84<9970,"/",IF(Besoin!O84<10120,"680000064 - OPTION OPTIMA 150PTS",IF(Besoin!O84<10250,"680000065 - OPTION OPTIMA 300PTS",IF(Besoin!O84<10400,"680000066 - OPTION OPTIMA 500PTS",IF(Besoin!O84<10800,"680000067 - OPTION OPTIMA 1000PTS",IF(Besoin!O84<12000,"680000068 - OPTION OPTIMA 2500PTS",IF(Besoin!O84<14000,"680000069 - OPTION OPTIMA 5000PTS",IF(Besoin!O84<20000,"680000070 - OPTION OPTIMA 10000PTS","LIMITE HAUTE ATTEINTE !!!")))))))) -> / | N18: =IF(I18="/","/",Besoin!H55) -> / | P18: /
C19: 7 | D19: Redondance des serveurs | I19: =IF(Besoin!M55="Oui","680000075 - OPTIMA Backup","/") -> / | N19: =IF(Besoin!M55="Oui",Besoin!H55-1,"/") -> / | P19: /
C20: 8 | D20: Licence OPTIMA poste Client 1x | I20: =IF(OR((Besoin!H57+Besoin!P57=0), AND(Besoin!H57="", Besoin!P57="")),"","680000071 - OPTIMA Viewer") | N20: =IF(Besoin!H57+Besoin!P57>0,Besoin!H57+Besoin!P57-FLOOR((Besoin!H57+Besoin!P57)/5,1)*5,"/") -> / | P20: /
C21: 9 | D21: Licence OPTIMA poste Client 5x | I21: =IF(OR((Besoin!H57+Besoin!P57=0), AND(Besoin!H57="", Besoin!P57="")),"",IF(Besoin!H57+Besoin!P57>4,"680000072 - OPTIMA Viewer (x5)","/")) | N21: =IF(Besoin!H57+Besoin!P57>4,FLOOR((Besoin!H57+Besoin!P57)/5,1),"/") -> / | P21: /
C22: 10 | D22: Option Protocole Supplémentaire | I22: / | N22: =IF(I22="","",IF(I22="/","",Besoin!H55)) | P22: /
C23: 11 | D23: Option SMS/mail | I23: =IF(Besoin!M53="Oui","680000076 - OPTIMA SMS/Mail","/") -> / | N23: =IF(I23="","",IF(I23="/","",Besoin!H55)) | P23: /
C24: 12 | D24: Option Main courante | I24: =IF(Besoin!F53="Oui","680000074 - OPTIMA Main courante","/") -> / | N24: =IF(I24="","",IF(I24="/","",Besoin!H55)) | P24: /
C25: 13 | D25: Option ESPA 4.4.4. | I25: / | N25: =IF(I25="","",IF(I25="/","",Besoin!H56)) | P25: /
C26: 14 | D26: Serveurs OPC | P26: /
P27: /
P28: /
C29: 15 | D29: Interfaces communications | P29: /
P30: /
P31: /
C32: 16 | D32: Routeurs | P32: /
P33: /
P34: /
A38: DETAIL DU TEMPS DE M.O SELON LES ELEMENTS TRANSMIS
D40: Désignation | J40: Commentaire | O40: Temps à prévoir
C41: 1 | D41: Temps de paramétrage et test PC | J41: Fait à l'agence | O41: =(Besoin!H55*8)+(Besoin!H57+Besoin!P57*4) -> 0 | P41: heures
C42: 2 | D42: Plan Autocad (nettoyage/formatage) | J42: =IF(Besoin!E36="NON"," ",Besoin!J38) -> 0 | K42: =IF(Besoin!E36="Oui","plans à nettoyer",IF(Besoin!E36="Non","Pas de plans à nettoyer")) -> FALSE | O42: =IF(Besoin!E36="Non","/",J42*0.5) -> 0 | P42: heures
C43: 3 | D43: Synoptiques (import/navigation) | J43: =IF(Besoin!E36="NON"," ",Besoin!G39) -> 0 | K43: =IF(Besoin!E36="Oui","plans à réaliser",IF(Besoin!E36="Non","Pas de plans à réaliser")) -> FALSE | O43: =IF(Besoin!E36="Non","/",IF(Besoin!K51="Oui",J43,J43*2)) -> 0 | P43: heures
C44: 4 | D44: Synoptiques suplémentaires MES | J44: =IF(Besoin!K51="Oui"," ",Besoin!Q51) -> 0 | K44: =IF(Besoin!K51="Non","plans à réaliser",IF(Besoin!K51="Oui","Pas de plans supplémentaires")) -> FALSE | O44: =IF(Besoin!K51="Oui","/",IF(Besoin!K52="Oui",J44,J44)) -> 0 | P44: heures
C45: 5 | D45: Nombre DA/DM (implantation) | J45: =Besoin!J81 -> 0 | O45: =(J45*0.033) -> 0 | P45: heures
C46: 6 | D46: Nombre DAS (implantation) | J46: =Besoin!J83 -> 0 | O46: =(J46*0.05) -> 0 | P46: heures
C47: 7 | D47: Nombre ZD (implantation) | J47: =Besoin!J80 -> 0 | O47: =(J47*0.05) -> 0 | P47: heures
C48: 8 | D48: Nombre centrale pour MAJ (importation) | J48: =Besoin!B17+Besoin!B19+Besoin!B21+Besoin!B13+Besoin!B25 -> 0 | O48: =(J48*0.25) -> 0 | P48: heures
C49: 9 | D49: Mise en service | J49: A définir par agence | O49: ???? | P49: heures
...

Sheet Evolution
A3: Révision | B3: Description | E3: A faire:
A4: 4 | B4: Changement calcul sur la question Doit-on fournir le(s) PC(s) :
B5: Ajout code article option SMS Mail
B6: Ajout du choix du type de licence: physique ou logicielle
B7: Correction du calcul des quantités à prévoir des licences Viewer x5
B8: Ajout du code article ESPA444
B9: Dévérouillage de la partie COMMENTAIRES
B10: Problème Ecran fourni par le client si PC fourni par le client: Faire apparaitre le "Oui" dans la colonne "fournit par le client" pour l'écran si le PC est fournit par le client.
B11: Apparition des quantités à prévoir même si fourni par le client
B12: Ajout de l'interface Easylon
B13: Ajout du nombre de symboles par plans
A15: 5 | B15: Calcul du nombre de "Pages supervision (import/navigation)" pour diviser par 2 le temps BE des plans de MES par rapport aux plans DI Suppresion des 10% si licence virtuelle
A16: 6 | B16: Calcul du nb de variables DA/DM x 3 pour ACTIVA1000 | E16: Ajouter l'information du nb maximum de 100 symboles par plan
B17: Calcul du nb de variables ZD x 1 pour ACTIVA1000 | E17: Ajouter le choix du type de licence: physique ou logicielle
B18: Calcul du nb de variables Fonction x 9 pour ACTIVCOM
B19: Calcul du nb de variables DCT x 3 pour ACTIVCOM
